Workbook

Sheet User Stories
A1: ID | B1: Area | C1: Feature | D1: Reference | E1: User Story | F1: Expected Behaviour | G1: Invocation | H1: Edge Cases / Validation | I1: Phase 1 Status | J1: Phase 2 Test Result | K1: Errors Found | L1: Phase 3 Fix | M1: Phase 4 Retest
A2: US-001 | B2: Research MCP | C2: Create research job | D2: mcp_server.create_research_job | E2: As an AI host, I give Oyster a plain-language brief so it returns a structured research plan and a persisted job. | F2: build_plan() runs; a research_jobs row is created; returns {job_id, created_at, plan} with questions, entities, query families, recommended sources, clarifications. | G2: create_research_job(brief, decision, market, time_horizon, audience, deliverable, required_sources, exclusions) | H2: Brief under 12 chars raises 'enough detail'. Non-gaming brief must NOT pull twitch/kick. | I2: Documented | J2: PASS | M2: PASS (re-verified green)
A3: US-002 | B3: Research MCP | C3: Add evidence | D3: mcp_server.add_evidence | E3: As a host, I store a finding with provenance so it appears in the dossier. | F3: Inserts research_evidence with content_hash dedup; published_at parsed from ISO; returns {evidence_id, collected_at}. | G3: add_evidence(job_id, source_type, url, title, excerpt, author, published_at, query, metadata) | H3: Duplicate (job_id, source_type, url, excerpt) updates collected_at, no dup row. Bad ISO published_at raises. | I3: Documented | J3: PASS | M3: PASS (re-verified green)
A4: US-003 | B4: Research MCP | C4: Fetch RSS | D4: mcp_server.fetch_rss | E4: As a host, I collect matching entries from a public feed. | F4: Fetches feed, stores entries matching any query term as source_type=rss, logs raw payload; returns {feed_url, matched, items, raw_response_id}. | G4: fetch_rss(job_id, feed_url, query_terms, limit) | H4: Non-public/redirect-to-private URL rejected. Empty query_terms stores all. feedparser.parse used. | I4: Documented | J4: PASS | K4: F4 (data quality, found in live Spider-Man run): feed summaries with HTML (e.g. Google News) were stored as raw <a> markup instead of readable text. | L4: Added _plain_text() to strip tags + unescape entities; applied to RSS title/excerpt/author. | M4: PASS (live re-run shows clean headlines; test_feed_html_is_reduced_to_readable_text)
A5: US-004 | B5: Research MCP | C5: Search X | D5: mcp_server.search_x | E5: As a host, I search recent X posts via official API. | F5: With bearer token, queries X recent search, stores posts as source_type=x; without token returns not_configured with fallbacks. | G5: search_x(job_id, query, max_results) | H5: No token -> {not_configured:true, connector:x_official, fallbacks:[...]}, not an error. | I5: Documented | J5: PASS | M5: PASS (re-verified green)
A6: US-005 | B6: Research MCP | C6: Inspect Discord invite | D6: mcp_server.inspect_discord_invite | E6: As a host, I capture public metadata for a Discord invite. | F6: Resolves invite code, GETs invite with counts, stores guild name/member/presence as source_type=discord. | G6: inspect_discord_invite(job_id, invite_url_or_code) | H6: Bad code raises 'invite code or ... URL'. 404 raises 'invalid or expired'. | I6: Documented | J6: PASS | M6: PASS (re-verified green)
A7: US-006 | B7: Research MCP | C7: Run Apify actor | D7: mcp_server.run_apify_actor | E7: As a host, I run a chosen Apify Actor for Reddit/X/other sources. | F7: With token, runs actor run-sync-get-dataset-items, stores rows; without token returns not_configured. | G7: run_apify_actor(job_id, actor_id, actor_input, source_type, limit) | H7: No token -> not_configured(apify). Empty actor_id raises 'Choose an Apify Actor ID'. | I7: Documented | J7: PASS | M7: PASS (re-verified green)
A8: US-007 | B8: Research MCP | C8: Search Twitch | D8: mcp_server.search_twitch | E8: As a host, I search arbitrary Twitch channels/topics. | F8: With client id+secret, OAuth then search/channels, stores results; without creds returns not_configured(twitch). | G8: search_twitch(job_id, query, limit) | H8: No creds -> not_configured with fallbacks (apify/crawl/capture). OAuth token logged as oauth_token (redacted). | I8: Documented | J8: PASS | M8: PASS (re-verified green)
A9: US-008 | B9: Research MCP | C9: Search Kick | D9: mcp_server.search_kick | E9: As a host, I search current Kick streams. | F9: With creds, OAuth then paginate livestreams filtered by query; without creds returns not_configured(kick). | G9: search_kick(job_id, query, pages) | H9: No creds -> not_configured. Token redacted. | I9: Documented | J9: PASS | M9: PASS (re-verified green)
A10: US-009 | B10: Research MCP | C10: Read Discord channel | D10: mcp_server.read_discord_channel | E10: As a host, I read messages from a channel the bot can access. | F10: With bot token, reads channel + messages, stores non-empty messages as source_type=discord_message; without token not_configured. | G10: read_discord_channel(job_id, channel_id, limit) | H10: No token -> not_configured(discord_messages). 403 raises grant-permission guidance. | I10: Documented | J10: PASS | M10: PASS (re-verified green)
A11: US-010 | B11: Research MCP | C11: Crawl web page | D11: mcp_server.crawl_web_page | E11: As a host, I extract readable text + links from a public page. | F11: Validates public URL, fetches via Scrapling, stores text + up to 100 links as source_type=web, logs raw payload. | G11: crawl_web_page(job_id, url, query) | H11: Private/local/reserved targets rejected (SSRF). HTTP>=400 raises. No extractable text raises with fallback hint. | I11: Documented | J11: PASS | M11: PASS (re-verified green)
A12: US-011 | B12: Research MCP | C12: Get dossier | D12: mcp_server.get_research_dossier | E12: As a host, I retrieve a job's evidence grouped with coverage and gaps. | F12: Returns {job, evidence[], coverage{source:count}, gaps[]}; gaps = recommended sources with zero evidence. | G12: get_research_dossier(job_id) | H12: Unknown job_id raises 'was not found'. content_hash stripped from output. | I12: Documented | J12: PASS | M12: PASS (re-verified green)
A13: US-012 | B13: Research MCP | C13: List jobs | D13: mcp_server.list_research_jobs | E13: As a host, I list recent jobs to resume prior work. | F13: Returns up to N recent jobs (id, brief, decision, status, timestamps) ordered by updated_at desc. | G13: list_research_jobs(limit) | H13: limit clamped 1..100. | I13: Documented | J13: PASS | M13: PASS (re-verified green)
A14: US-013 | B14: Research MCP | C14: Connector status | D14: mcp_server.connector_status | E14: As a host, I check which connectors are ready and how to set up or fall back. | F14: Returns per-connector {ready, setup, fallbacks/scope...} derived from CONNECTOR_GUIDES + READY_CHECKS. | G14: connector_status() | H14: Never returns secret values. twitch/kick/apify/discord_messages all include fallbacks. | I14: Documented | J14: PASS | M14: PASS (re-verified green)
A15: US-014 | B15: Research MCP | C15: Export research report | D15: mcp_server.export_research_report | E15: As a host, I export a job to a folder of files. | F15: Writes report.md/html, evidence.json/csv, raw_responses.jsonl to output/research-job-<id>-<slug>/; returns {folder, files, evidence_count, raw_count}. | G15: export_research_report(job_id) | H15: Pipes in cells escaped; CSV formula-injection guarded; output_dir anchored to project root. | I15: Documented | J15: PASS | M15: PASS (re-verified green)
A16: US-015 | B16: Research MCP | C16: Browser capture mission | D16: mcp_server.get_browser_capture_mission | E16: As a host, I turn a brief into browser-capture terms/questions. | F16: Returns {job_id, brief, research_questions, look_for terms, exclusions, instructions} for the active job. | G16: get_browser_capture_mission(job_id) | H16: Only active jobs; unknown/inactive job raises 'was not found'. | I16: Documented | J16: PASS | M16: PASS (re-verified green)
... A26: US-025 | B26: Connectors | C26: Raw traffic logging | D26: raw_log.record_raw | E26: As an operator, connector HTTP payloads are stored redacted for provenance. | F26: Stores redacted payload in raw_responses keyed by research_job_id; dedups by body_hash; best-effort (never breaks a connector). | G26: automatic in each connector | H26: Secrets in URL/headers/oauth body redacted; >2MB truncated with marker. | I26: Documented | J26: PASS | M26: PASS (re-verified green)
A27: US-026 | B27: Export | C27: Per-job export files | D27: export.export_job | E27: As a user, I export a job to shareable files. | F27: Creates folder with report.md, report.html, evidence.json, evidence.csv, raw_responses.jsonl. | G27: export_research_report / control center | H27: Slug from brief; pipes escaped; CSV guards =+-@ cells. | I27: Documented | J27: PASS | L27: Added job_folder() helper so 'Open folder' reuses an existing export. | M27: PASS (re-verified; export files intact)
A28: US-027 | B28: Export | C28: Gaps unlock section | D28: export._gaps | E28: As a user, the report tells me how to unlock each empty source. | F28: For each gap, maps source->connector guide and lists setup + fallbacks in report.md. | G28: export output | H28: rss/web always-ready gaps show scope not creds. | I28: Documented | J28: FAIL | K28: F2 (UX): export gap section renders an empty heading (e.g. '### rss') for always-ready sources that have no setup/fallbacks — reads as a bare, confusing heading. | L28: Gap section now renders the connector guide's scope for always-ready sources (rss/web) instead of an empty heading. | M28: PASS (test_always_ready_source_gap_has_guidance_not_empty_heading)
A29: US-028 | B29: Capture | C29: Create pairing code | D29: capture.create_pairing_code | E29: As a user, I generate a one-time code to pair the extension. | F29: Creates a hashed, 10-min single-use code; returns {pairing_code, expires_at}. | G29: control center 'Create pairing code' | H29: TTL clamped 1..30 min. | I29: Documented | J29: PASS | M29: PASS (re-verified green)
A30: US-029 | B30: Capture | C30: Exchange pairing code | D30: capture.exchange_pairing_code | E30: As the extension, I trade a code + extension id for a bearer token. | F30: Single-use code -> stores hashed token bound to extension id; returns {client_id, token, extension_id}. | G30: extension pairing | H30: Reused/expired code rejected. Invalid extension id rejected. | I30: Documented | J30: PASS | M30: PASS (re-verified green)
A31: US-030 | B31: Capture | C31: Authenticate + origin bind | D31: capture.authenticate | E31: As the server, I accept only the paired extension origin or local UI. | F31: Validates token hash (constant-time) and origin allowlist; updates last_used. | G31: every capture request | H31: Hostile origin -> PermissionError. Revoked token -> PermissionError. | I31: Documented | J31: PASS | M31: PASS (re-verified green)
A32: US-031 | B32: Capture | C32: Revoke client | D32: capture.revoke_client | E32: As a user, I revoke a paired browser immediately. | F32: Sets revoked_at; subsequent auth and submissions fail. | G32: POST /api/capture/revoke | H32: Double revoke raises 'not found or already revoked'. | I32: Documented | J32: PASS | M32: PASS (re-verified green)
A33: US-032 | B33: Capture | C33: Capture mission | D33: capture.mission | E33: As the extension, I get the mission terms for the active job. | F33: Returns brief, research_questions, look_for terms, exclusions for an active job. | G33: GET /api/capture/jobs/{id}/mission | H33: Inactive/unknown job raises 'was not found'. | I33: Documented | J33: PASS | M33: PASS (re-verified green)
A34: US-033 | B34: Capture | C34: Submit candidate | D34: capture.submit | E34: As a researcher, I queue a selected/scanned excerpt for review (not saved yet). | F34: Inserts a pending browser_captures row with anonymized author; audit 'capture.submitted'. | G34: POST /api/capture/pending | H34: Bad url/excerpt/mode/question rejected. Author anonymized by default. | I34: Documented | J34: PASS | M34: PASS (re-verified green)
A35: US-034 | B35: Capture | C35: Review approve/reject | D35: capture.review | E35: As a researcher, I approve one candidate to promote it to evidence, or reject it. | F35: Approve -> dedup insert into research_evidence, scrub staging; reject -> discard; audit event. | G35: POST/DELETE /api/capture/pending/{id} | H35: Other client cannot see/mutate. Already-reviewed raises. | I35: Documented | J35: PASS | M35: PASS (re-verified green)
A36: US-035 | B36: Capture | C36: Direct approve (idempotent) | D36: capture.approve_direct | E36: As the extension, I atomically submit+approve a capture, safe to retry. | F36: Advisory-locked; idempotent by client_capture_id; promotes evidence; audit 'capture.approved'. | G36: POST /api/capture/approve | H36: Retry returns idempotent:true, same evidence_id. | I36: Documented | J36: PASS | M36: PASS (re-verified green)
A37: US-036 | B37: Capture | C37: Delete capture/evidence | D37: capture.delete_capture | E37: As a researcher, I delete a promoted capture and its evidence. | F37: Deletes evidence + scrubs/deletes staging, client-scoped; audit 'capture.deleted'. | G37: DELETE /api/capture/evidence/{id} | H37: Wrong client cannot delete. | I37: Documented | J37: PASS | M37: PASS (re-verified green)
A38: US-037 | B38: Capture | C38: Expire pending | D38: capture.expire_pending | E38: As the system, stale pending candidates are purged. | F38: Pending past expires_at -> status expired, content scrubbed; audit 'capture.expired'. | G38: automatic on list | H38: 24h default TTL. | I38: Documented | J38: PASS | M38: PASS (re-verified green)
A39: US-038 | B39: Sessions | C39: Request session | D39: capture.request_session | E39: As a host, I request an approval-gated traffic session for one domain. | F39: Creates 'requested' session; normalizes domain; rejects duplicates and inactive jobs. | G39: request_browser_traffic_session | H39: scheme/port/path/IP/localhost rejected; dup live session rejected. | I39: Documented | J39: PASS | M39: PASS (re-verified green)
A40: US-039 | B40: Sessions | C40: Approve session | D40: capture.approve_session | E40: As a researcher, I approve a session once, binding it to my browser for <=30 min. | F40: Sets approved, client_id, expires_at=now+min(ttl,30); returns session summary; audit 'session.approved'. | G40: POST /api/capture/sessions/{id}/approve | H40: Requires approved_by_user; revoked client rejected; only 'requested' approvable. | I40: Documented | J40: PASS | M40: PASS (re-verified green)
... A68: US-067 | B68: Control Center | C68: Create weekly report | D68: control_center /api/run report | E68: As a user, I generate this week's report. | F68: Starts background report subprocess for the current Monday week. | G68: 'Create weekly report' button | H68: Gated on ready. | I68: Documented | J68: PASS | M68: PASS (re-verified green)
A69: US-068 | B69: Control Center | C69: Open report/folder | D69: control_center.open_path /api/open | E69: As a user, I open a report or the output folder in my file browser. | F69: Opens weekly/fresh/output/research target cross-platform. | G69: 'Open weekly/fresh/output' + per-job 'Open folder' | H69: No report -> friendly error. research kind re-exports first. | I69: Documented | J69: PASS | L69: 'Open folder' for a research job now opens the existing folder via job_folder(); exports only when the folder is absent (no longer re-exports on every click). | M69: PASS (test_open_research_folder_reuses_existing_export)
A70: US-069 | B70: Control Center | C70: Research jobs panel | D70: control_center /api/research/jobs + export | E70: As a user, I list research jobs and export any to files. | F70: Lists up to 50 jobs; per-job Export writes folder; Open opens it. | G70: Research jobs panel buttons | H70: Export requires X-Pulse-Token. job_id<=0 rejected. | I70: Documented | J70: PASS | M70: PASS (re-verified green)
A71: US-070 | B71: Control Center | C71: Create pairing code | D71: control_center /api/capture/pairing-code | E71: As a user, I create a one-time code to pair the extension. | F71: Returns a 10-min single-use code shown in the UI. | G71: 'Create one-time pairing code' button | H71: Gated on ready else opens Setup. | I71: Documented | J71: PASS | M71: PASS (re-verified green)
A72: US-071 | B72: Control Center | C72: Job progress polling | D72: control_center start_job/run_job /api/job | E72: As a user, I see live progress of a running action. | F72: Background thread runs subprocess; UI polls /api/job every 1s until non-running. | G72: automatic after run | H72: Unknown job id -> 404. Details capped 4000 chars. | I72: Documented | J72: PASS | M72: PASS (re-verified green)
A73: US-072 | B73: Control Center | C73: Session token security | D73: control_center X-Pulse-Token | E73: As a user, stale dashboard sessions can't mutate state. | F73: Mutating POSTs require the per-process token; after restart the old page gets 403 refresh prompt. | G73: any mutating action | H73: Token rotates each restart. | I73: Documented | J73: PASS | M73: PASS (re-verified green)
A74: US-073 | B74: Control Center | C74: Origin/host guard | D74: control_center.capture_client + do_OPTIONS | E74: As an operator, only the paired extension origin and exact local host are accepted. | F74: Capture requests require exact Host + chrome-extension origin; CORS preflight limited to that origin. | G74: extension requests | H74: Hostile origin/host -> 403. | I74: Documented | J74: PASS | M74: PASS (re-verified green)
A75: US-074 | B75: Control Center | C75: Rate limiting | D75: control_center.enforce_rate | E75: As an operator, capture and pairing endpoints are rate-limited. | F75: Sliding 60s window: capture 120/min per token, pair 10/min per extension id. | G75: capture/pair requests | H75: Exceed -> 'Too many' 403. | I75: Documented | J75: PASS | M75: PASS (re-verified green)
A76: US-075 | B76: Extension Options | C76: Pair browser | D76: options.pair | E76: As a user, I pair the extension with a one-time code. | F76: POSTs code to /api/capture/pair, stores token+baseUrl. | G76: Options 'Pair browser' | H76: Empty code -> error. baseUrl forced local http. | I76: Documented | J76: PASS | M76: PASS (re-verified green)
...

Sheet Summary
A1: Research Oyster — Feature Status Summary
A3: Metric | B3: Count
A4: Total user stories | B4: =COUNTA('User Stories'!A2:A100)
A5: Phase 1 documented | B5: =COUNTIF('User Stories'!I2:I100,"Documented")
A6: Phase 2 tested (non-blank) | B6: =COUNTIF('User Stories'!J2:J100,"?*")
A7: Phase 2 PASS | B7: =COUNTIF('User Stories'!J2:J100,"PASS*")
A8: Phase 2 FAIL | B8: =COUNTIF('User Stories'!J2:J100,"FAIL*")
A9: Errors logged | B9: =COUNTIF('User Stories'!K2:K100,"?*")
A10: Fixes applied | B10: =COUNTIF('User Stories'!L2:L100,"?*")
A11: Phase 4 PASS | B11: =COUNTIF('User Stories'!M2:M100,"PASS*")
A14: Area | B14: Stories
A15: Research MCP | B15: =COUNTIF('User Stories'!B2:B100,"Research MCP")
A16: Planner | B16: =COUNTIF('User Stories'!B2:B100,"Planner")
A17: Store | B17: =COUNTIF('User Stories'!B2:B100,"Store")
A18: Connectors | B18: =COUNTIF('User Stories'!B2:B100,"Connectors")
A19: Export | B19: =COUNTIF('User Stories'!B2:B100,"Export")
A20: Capture | B20: =COUNTIF('User Stories'!B2:B100,"Capture")
A21: Sessions | B21: =COUNTIF('User Stories'!B2:B100,"Sessions")
A22: CLI | B22: =COUNTIF('User Stories'!B2:B100,"CLI")
A23: Collectors | B23: =COUNTIF('User Stories'!B2:B100,"Collectors")
A24: Reporting | B24: =COUNTIF('User Stories'!B2:B100,"Reporting")
A25: Config | B25: =COUNTIF('User Stories'!B2:B100,"Config")
A26: Control Center | B26: =COUNTIF('User Stories'!B2:B100,"Control Center")
A27: Extension Options | B27: =COUNTIF('User Stories'!B2:B100,"Extension Options")
A28: Extension Popup | B28: =COUNTIF('User Stories'!B2:B100,"Extension Popup")
A29: Extension Background | B29: =COUNTIF('User Stories'!B2:B100,"Extension Background")
A30: Launcher | B30: =COUNTIF('User Stories'!B2:B100,"Launcher")

Sheet Legend
A1: How to read this workbook
A3: This is the single canonical tracker for every Research Oyster feature.
A5: Columns:
A6: Phase 1 Status — 'Documented' once the user story + expected behaviour are written.
A7: Phase 2 Test Result — 'PASS' or 'FAIL: <why>' after testing the story against the code.
A8: Errors Found — any logistical/UX/logic error observed during Phase 2.
A9: Phase 3 Fix — what was changed to resolve the error (commit-level).
A10: Phase 4 Retest — 'PASS' after re-testing post-fix (or 'N/A' if nothing to fix).
A12: The Summary sheet counts each status live with formulas.
A13: IDs are stable (US-001..). Areas are colour-tagged on the User Stories sheet.
